Workbook

Sheet Descripciones
A1: PARÁMETROS DE DESCARGA AUTOMÁTICA DESDE GPS
A2: Xm (E-UTM) | B2: Easting UTM del punto de ubicación de antena DGPS.
A3: Ym (N-UTM) | B3: Northing UTM del punto de ubicación de antena DGPS.
A4: Zm (WGS84) | B4: Altitud sobre elipsoide WGS84 del punto de ubicación de antena DGPS.
A5: Tipo punto | B5: Código (propio nuestro) punto DGPS: RTK=Real Time Kinematics, RTCM=Estándar de la "Radio Technical Commission for Maritime Services", PP=Post-proceso.
A6: D ant | B6: Altura de la antena DGPS respecto al punto que se desea medir (en nuestro caso, la parte superior de la estaca de medida, sea la estaca real o la auxiliar). Se utiliza para corregir por la altura del adaptador de antena o la diferencia de altura de distintos tipos de antena (en versiones anteriores, era un parámetro de descarga automática desde el GPS pero ahora es un parámetro de anotación manual; ésta es la razón de su ubicación en la hoja -se ha mantenido la original-, aunque se ha cambiado el código de color del campo, para hacerlo coincidir con el de parámetro de anotación manual).
A7: Xr (E-UTM) | B7: Easting UTM del punto base DGPS respecto al que se ha tomado la medida.
A8: Yr (N-UTM) | B8: Northing UTM del punto base DGPS respecto al que se ha tomado la medida.
A9: Zr (WGS84) | B9: Altitud sobre el elipsoide WGS84 del punto base DGPS respecto al que se ha tomado la medida.
A11: PARÁMETROS MEDIDOS EN CAMPO
A12: he(m) | B12: Distancia desde el nivel de la superficie de la nieve hasta el extremo superior de la estaca real, medido a lo largo de longitud de ésta, esté vertical o inclinada (positivo para estaca que aflora; negativo para estaca hundida).
A13: hm(m) | B13: Distancia desde el nivel de la superficie de la nieve hasta el extremo superior de la estaca en la que se efectúa la medida DGPS, sea la propia estaca o una estaca auxiliar (DEBE SER SIEMPRE POSITIVO, para que la antena "vea" a los satélites).
A14: e(deg) | B14: Ángulo de elevación (en grados sexagesimales, de 0 a 90º) de la estaca respecto a la horizontal. Es el complementario del ángulo cenital (o desviación respecto a la vertical).
A15: fm(deg) | B15: Rumbo (en grados sexagesimales, 0 a 360º) de la estaca inclinada, medido desde el norte magnético en sentido de las agujas del reloj (denominado retrógrado). En la hoja de cálculo se convertirá a azimut geográfico, teniendo en cuenta la declinación magnética (13º Este en Livingston, positivo a efectos de cálculo) y convergencia de cuadrícula (2,3º aprox en Johnsons.Hurd).
A16: a(deg) | B16: Pendiente (en grados sexagesimales, de 0 a 90º) de la superficie del glaciar en la dirección de la inclinación de la estaca (sólo necesario para estacas inclinadas en zonas de pendiente apreciable de la superficie).
A17: H (m) valores individuales | B17: Espesor de nieve junto a la estaca, medido con sonda de nieve. Se toman varios valores, al menos cinco si son parecidos, e incluso más si difieren significativamente (los rehielos pueden falsear esta medida). Si un número de ellos tienen valores similares y otros difieren significativamente, sólo los primeros se utilizarán para la media, pero todos los valores quedarán registrados (separados en utilizados y no utilizados en la media).
A18: l(m) | B18: Longitud total de la estaca (incluyendo parte enterrada). Para estaca ampliada uniendo un tramo a una estaca existente, sólo longitud del último tramo.
A20: PARÁMETROS CALCULADOS AUTOMÁTICAMENTE EN LA HOJA
A21: H(m) | B21: Media de los valores del espesor de nieve H.
A22: l(m) | B22: Ver definición en "párámetros de anotación manual". Para estacas inclinadas en zona de ablación, si l no se conoce se estima automáticamente.
A23: h(m) | B23: Distancia desde el nivel de la superficie de la nieve hasta el extremo superior de la estaca vertical (si estuviera inclinada, tras devolverla virtualmente a la posición vertical). Para estaca vertical, coincide con he.
A24: X,Y,Z | B24: Coordenadas X, (Easting) e Y (Northing) UTM y altitud, sobre el elipsoide WGS84, del extremo superior de la estaca.
A25: Dh (m) | B25: Dh=h(hoja mto.)-h(hoja ordinaria), cambio de la longitud de la estaca al efectuar mantenimiento (positivo, si extensión; negativo, si replantado). Se calcula en la hoja de mantenimiento.

Sheet Estacas Hurd
A1: Campaña | B1: 2023-2024 | C1: Tanda | D1: a | E1: Operador | F1: Ricardo Rodríguez Cielos | G1: Instrumento | H1: Trimble R8S+TSC3(bluetooth) | L1: X0,Y0,Z0 | M1: 633905.23 | N1: 3049240.4 | O1: =56.39-0.11 -> 56.28 | P1: Estacas HURD 1ª fase 2023/2024
A2: Id. estaca | B2: Fecha | C2: Hora (UT) | D2: ¿Mto.? | E2: PreMtoFecha | F2: PreMtoHora | G2: Fichero fuente | H2: Xm (E-UTM) | I2: Ym (N-UTM) | J2: Zm (WGS84) | K2: Código | L2: Dant | M2: Xr (E-UTM) | N2: Yr (N-UTM) | O2: Zr (WGS84) | P2: Comentarios sobre medida GPS | Q2: he (m) | R2: hm (m) | S2: e(deg) | T2: fm(deg) | Y2: H usados en media (m) | AH2: H no usados en media (m) | AM2: H (m) | AN2: l (m) | AO2: Comentarios medidas manuales | AP2: Recursos gráficos asociados | AQ2: h (m) | AR2: X (E-UTM) | AS2: Y (N-UTM) | AT2: Z (WGS84) | AU2: ¿40? | AV2: Coment. sobre medida corregida | AX2: a(deg)
B3: dd-mm-aa | C3: hh:mm | D3: Dejar NO | E3: Dejar vacío | F3: Dejar vacío | H3: xxxxxx,xx | I3: yyyyyyy,yy | J3: zzz,zz | M3: xxxxxx,xxx | N3: yyyyyyy,yyy | O3: zzz,zzz | Q3: hh,hh | R3: hh,hh | S3: g | T3: g | U3: H1 | V3: H2 | W3: H3 | X3: H4 | Y3: H5 | Z3: H6 | AA3: H7 | AB3: H8 | AC3: H9 | AD3: H1 | AE3: H2 | AF3: H3 | AG3: H4 | AH3: H5 | AI3: H6 | AJ3: H7 | AK3: H8 | AL3: H9 | AM3: HH,HH | AN3: ll,ll | AQ3: hh,hh | AR3: xxxxxx,xx | AS3: yyyyyyy,yy | AT3: zzz,zz
A5: EH01 | B5: 03-01-24 | C5: 13:53 | D5: NO | G5: rrc_20240103_gla | H5: 634703.47 | I5: 3046967.8 | J5: 354.349 | K5: RTK | L5: 1.96 | M5: 633905.23 | N5: 3049240.4 | O5: 56.39 | P5: Altura antena 1,96 incluida en Zm vía data controller; por eso se corrigen en Excel Delta_ant y hm | Q5: 0.11 | R5: 2.07 | S5: 90 | U5: 1.75 | V5: 1.78 | W5: 1.85 | X5: 1.65 | Y5: 1.82 | AM5: =AVERAGE(U5:AC5) -> 1.77 | AN5: 3.67 | AQ5: =AN5-(AN5-Q5)*(SIN((S5+AX5)*PI()/180))/(COS(AX5*PI()/180)) -> 0.11 | AR5: =H5+($M$1-M5)-(AN5-Q5)*(COS(S5*PI()/180))*(SIN((T5+13+2.3)*PI()/180)) -> 634703.47 | AS5: =I5+($N$1-N5)-(AN5-Q5)*(COS(S5*PI()/180))*(COS((T5+13+2.3)*PI()/180)) -> 3046967.8 | AT5: =J5+($O$1-O5)-R5+AN5-(AN5-Q5)*(SIN(S5*PI()/180))-L5 -> 350.319
A6: EH02 | B6: 03-01-24 | C6: 14:10 | D6: NO | G6: rrc_20240103_gla | H6: 634294.31 | I6: 3046968.7 | J6: 334.372 | K6: RTK | L6: 1.96 | M6: 633905.23 | N6: 3049240.4 | O6: 56.39 | P6: Altura antena 1,96 incluida en Zm vía data controller; por eso se corrigen en Excel Delta_ant y hm | Q6: 0.31 | R6: 2.27 | S6: 90 | U6: 2.1 | V6: 2.05 | W6: 2 | X6: 2.1 | Y6: 2.05 | AM6: =AVERAGE(U6:AC6) -> 2.06 | AN6: 3.67 | AQ6: =AN6-(AN6-Q6)*(SIN((S6+AX6)*PI()/180))/(COS(AX6*PI()/180)) -> 0.31 | AR6: =H6+($M$1-M6)-(AN6-Q6)*(COS(S6*PI()/180))*(SIN((T6+13+2.3)*PI()/180)) -> 634294.31 | AS6: =I6+($N$1-N6)-(AN6-Q6)*(COS(S6*PI()/180))*(COS((T6+13+2.3)*PI()/180)) -> 3046968.7 | AT6: =J6+($O$1-O6)-R6+AN6-(AN6-Q6)*(SIN(S6*PI()/180))-L6 -> 330.342
A7: EH03 | B7: 03-01-24 | C7: 14:21 | D7: NO | G7: rrc_20240103_gla | H7: 633935.57 | I7: 3046873.7 | J7: 314.761 | K7: RTK | L7: 1.96 | M7: 633905.23 | N7: 3049240.4 | O7: 56.39 | P7: Altura antena 1,96 incluida en Zm vía data controller; por eso se corrigen en Excel Delta_ant y hm | Q7: 0.03 | R7: 1.99 | S7: 90 | U7: 1.95 | V7: 1.9 | W7: 1.9 | X7: 2 | Y7: 2 | AM7: =AVERAGE(U7:AC7) -> 1.95 | AN7: 3.67 | AQ7: =AN7-(AN7-Q7)*(SIN((S7+AX7)*PI()/180))/(COS(AX7*PI()/180)) -> 0.03 | AR7: =H7+($M$1-M7)-(AN7-Q7)*(COS(S7*PI()/180))*(SIN((T7+13+2.3)*PI()/180)) -> 633935.57 | AS7: =I7+($N$1-N7)-(AN7-Q7)*(COS(S7*PI()/180))*(COS((T7+13+2.3)*PI()/180)) -> 3046873.7 | AT7: =J7+($O$1-O7)-R7+AN7-(AN7-Q7)*(SIN(S7*PI()/180))-L7 -> 310.731
A8: EH04 | B8: 03-01-24 | C8: 14:31 | D8: NO | G8: rrc_20240103_gla | H8: 633559.76 | I8: 3046667 | J8: 282.94 | K8: RTK | L8: 1.96 | M8: 633905.23 | N8: 3049240.4 | O8: 56.39 | P8: Altura antena 1,96 incluida en Zm vía data controller; por eso se corrigen en Excel Delta_ant y hm | Q8: 0.3 | R8: 2.26 | S8: 90 | U8: 1.85 | V8: 1.85 | W8: 1.85 | X8: 1.83 | Y8: 1.82 | AM8: =AVERAGE(U8:AC8) -> 1.84 | AN8: 3.67 | AQ8: =AN8-(AN8-Q8)*(SIN((S8+AX8)*PI()/180))/(COS(AX8*PI()/180)) -> 0.3 | AR8: =H8+($M$1-M8)-(AN8-Q8)*(COS(S8*PI()/180))*(SIN((T8+13+2.3)*PI()/180)) -> 633559.76 | AS8: =I8+($N$1-N8)-(AN8-Q8)*(COS(S8*PI()/180))*(COS((T8+13+2.3)*PI()/180)) -> 3046667 | AT8: =J8+($O$1-O8)-R8+AN8-(AN8-Q8)*(SIN(S8*PI()/180))-L8 -> 278.91
A9: EH05 | B9: 03-01-24 | C9: 14:39 | D9: NO | G9: rrc_20240103_gla | H9: 633270.7 | I9: 3046419.7 | J9: 262.392 | K9: RTK | L9: 0.001 | M9: 633905.23 | N9: 3049240.4 | O9: 56.39 | P9: Altura antena 0,001 incluida en Zm vía data controller; por eso se corrigen en Excel Delta_ant y hm. Sobre estaca | Q9: 1.03 | R9: 1.031 | S9: 90 | U9: 1.23 | V9: 1.25 | W9: 1.2 | X9: 1.22 | Y9: 1.23 | AM9: =AVERAGE(U9:AC9) -> 1.226 | AN9: 3.67 | AQ9: =AN9-(AN9-Q9)*(SIN((S9+AX9)*PI()/180))/(COS(AX9*PI()/180)) -> 1.03 | AR9: =H9+($M$1-M9)-(AN9-Q9)*(COS(S9*PI()/180))*(SIN((T9+13+2.3)*PI()/180)) -> 633270.7 | AS9: =I9+($N$1-N9)-(AN9-Q9)*(COS(S9*PI()/180))*(COS((T9+13+2.3)*PI()/180)) -> 3046419.7 | AT9: =J9+($O$1-O9)-R9+AN9-(AN9-Q9)*(SIN(S9*PI()/180))-L9 -> 262.28
A10: EH06 | B10: 03-01-24 | C10: 14:47 | D10: NO | G10: rrc_20240103_gla | H10: 632986.36 | I10: 3046150.6 | J10: 214.308 | K10: RTK | L10: 1.96 | M10: 633905.23 | N10: 3049240.4 | O10: 56.39 | P10: Altura antena 1,96 incluida en Zm vía data controller; por eso se corrigen en Excel Delta_ant y hm | Q10: 0.14 | R10: 2.1 | S10: 90 | U10: 0.86 | V10: 0.9 | W10: 0.96 | X10: 0.85 | Y10: 0.9 | AM10: =AVERAGE(U10:AC10) -> 0.894 | AN10: 3.67 | AQ10: =AN10-(AN10-Q10)*(SIN((S10+AX10)*PI()/180))/(COS(AX10*PI()/180)) -> 0.14 | AR10: =H10+($M$1-M10)-(AN10-Q10)*(COS(S10*PI()/180))*(SIN((T10+13+2.3)*PI()/180)) -> 632986.36 | AS10: =I10+($N$1-N10)-(AN10-Q10)*(COS(S10*PI()/180))*(COS((T10+13+2.3)*PI()/180)) -> 3046150.6 | AT10: =J10+($O$1-O10)-R10+AN10-(AN10-Q10)*(SIN(S10*PI()/180))-L10 -> 210.278
A11: EH07
A12: EH08
A13: EH09
A14: EH10 | B14: 03-01-24 | C14: 13:38 | D14: NO | G14: rrc_20240103_gla | H14: 634151.66 | I14: 3047372.5 | J14: 314.997 | K14: RTK | L14: 1.96 | M14: 633905.23 | N14: 3049240.4 | O14: 56.39 | P14: Altura antena 1,96 incluida en Zm vía data controller; por eso se corrigen en Excel Delta_ant y hm. A ras de nieve, pero se pone 0,01 para evitar errores | Q14: 0.01 | R14: 1.97 | S14: 90 | U14: 1.98 | V14: 2.02 | W14: 1.95 | X14: 1.94 | Y14: 2.05 | AM14: =AVERAGE(U14:AC14) -> 1.988 | AN14: 3.67 | AQ14: =AN14-(AN14-Q14)*(SIN((S14+AX14)*PI()/180))/(COS(AX14*PI()/180)) -> 0.01 | AR14: =H14+($M$1-M14)-(AN14-Q14)*(COS(S14*PI()/180))*(SIN((T14+13+2.3)*PI()/180)) -> 634151.66 | AS14: =I14+($N$1-N14)-(AN14-Q14)*(COS(S14*PI()/180))*(COS((T14+13+2.3)*PI()/180)) -> 3047372.5 | AT14: =J14+($O$1-O14)-R14+AN14-(AN14-Q14)*(SIN(S14*PI()/180))-L14 -> 310.967
A15: EH11 | B15: 03-01-24 | C15: 16:59 | D15: NO | G15: rrc_20240103_gla | H15: 633792.12 | I15: 3047682.5 | J15: 289.689 | K15: RTK | L15: 0 | M15: 633905.23 | N15: 3049240.4 | O15: 56.39 | P15: Altura antena 0,001 incluida en Zm vía data controller; por eso se corrigen en Excel Delta_ant y hm. Sobre estaca | Q15: 1.29 | R15: 1.29 | S15: 90 | U15: 1 | V15: 1 | W15: 0.95 | X15: 0.95 | Y15: 1 | AM15: =AVERAGE(U15:AC15) -> 0.98 | AN15: 3.67 | AQ15: =AN15-(AN15-Q15)*(SIN((S15+AX15)*PI()/180))/(COS(AX15*PI()/180)) -> 1.29 | AR15: =H15+($M$1-M15)-(AN15-Q15)*(COS(S15*PI()/180))*(SIN((T15+13+2.3)*PI()/180)) -> 633792.12 | AS15: =I15+($N$1-N15)-(AN15-Q15)*(COS(S15*PI()/180))*(COS((T15+13+2.3)*PI()/180)) -> 3047682.5 | AT15: =J15+($O$1-O15)-R15+AN15-(AN15-Q15)*(SIN(S15*PI()/180))-L15 -> 289.579
A16: EH12
A17: EH13
A18: EH14
A19: EH15
A20: EH16
A21: EH17
A22: EH18
A23: EH19
A24: EH20 | B24: 04-01-24 | C24: 16:52 | D24: NO | G24: rrc_20240104_gla | H24: 634601.78 | I24: 3046411.7 | J24: 323.513 | K24: RTK | L24: 1.1 | M24: 633905.23 | N24: 3049240.4 | O24: 56.39 | P24: Altura antena 1,1 incluida en Zm vía data controller; por eso se corrigen en Excel Delta_ant y hm | Q24: 0.2 | R24: 1.3 | S24: 90 | U24: 1.7 | V24: 1.75 | W24: 1.7 | X24: 1.83 | Y24: 1.8 | AM24: =AVERAGE(U24:AC24) -> 1.756 | AN24: 3.67 | AQ24: =AN24-(AN24-Q24)*(SIN((S24+AX24)*PI()/180))/(COS(AX24*PI()/180)) -> 0.2 | AR24: =H24+($M$1-M24)-(AN24-Q24)*(COS(S24*PI()/180))*(SIN((T24+13+2.3)*PI()/180)) -> 634601.78 | AS24: =I24+($N$1-N24)-(AN24-Q24)*(COS(S24*PI()/180))*(COS((T24+13+2.3)*PI()/180)) -> 3046411.7 | AT24: =J24+($O$1-O24)-R24+AN24-(AN24-Q24)*(SIN(S24*PI()/180))-L24 -> 321.203
A25: EH21
A26: EH22 | B26: 04-01-24 | C26: 16:22 | D26: NO | G26: rrc_20240104_gla | H26: 633897.52 | I26: 3046229.5 | J26: 288.625 | K26: RTK | L26: 0.88 | M26: 633905.23 | N26: 3049240.4 | O26: 56.39 | P26: Altura antena 0,88 incluida en Zm vía data controller; por eso se corrigen en Excel Delta_ant y hm | Q26: 0.46 | R26: 1.34 | S26: 90 | U26: 1.47 | V26: 1.55 | W26: 1.46 | X26: 1.46 | Y26: 1.36 | AM26: =AVERAGE(U26:AC26) -> 1.46 | AN26: 3.67 | AQ26: =AN26-(AN26-Q26)*(SIN((S26+AX26)*PI()/180))/(COS(AX26*PI()/180)) -> 0.46 | AR26: =H26+($M$1-M26)-(AN26-Q26)*(COS(S26*PI()/180))*(SIN((T26+13+2.3)*PI()/180)) -> 633897.52 | AS26: =I26+($N$1-N26)-(AN26-Q26)*(COS(S26*PI()/180))*(COS((T26+13+2.3)*PI()/180)) -> 3046229.5 | AT26: =J26+($O$1-O26)-R26+AN26-(AN26-Q26)*(SIN(S26*PI()/180))-L26 -> 286.755
A27: EH23 | B27: 03-01-24 | C27: 14:58 | D27: NO | G27: rrc_20240103_gla | H27: 633433.35 | I27: 3046020.4 | J27: 254.229 | K27: RTK | L27: 1.96 | M27: 633905.23 | N27: 3049240.4 | O27: 56.39 | P27: Altura antena 1,96 incluida en Zm vía data controller; por eso se corrigen en Excel Delta_ant y hm | Q27: 0.27 | R27: 2.23 | S27: 90 | U27: 1.9 | V27: 2 | W27: 1.83 | X27: 1.83 | Y27: 1.8 | AM27: =AVERAGE(U27:AC27) -> 1.872 | AN27: 3.67 | AQ27: =AN27-(AN27-Q27)*(SIN((S27+AX27)*PI()/180))/(COS(AX27*PI()/180)) -> 0.27 | AR27: =H27+($M$1-M27)-(AN27-Q27)*(COS(S27*PI()/180))*(SIN((T27+13+2.3)*PI()/180)) -> 633433.35 | AS27: =I27+($N$1-N27)-(AN27-Q27)*(COS(S27*PI()/180))*(COS((T27+13+2.3)*PI()/180)) -> 3046020.4 | AT27: =J27+($O$1-O27)-R27+AN27-(AN27-Q27)*(SIN(S27*PI()/180))-L27 -> 250.199
A28: EH24
A29: EH25 | B29: 03-01-24 | C29: 16:34 | D29: NO | G29: rrc_20240103_gla | H29: 633199.86 | I29: 3046652.4 | J29: 257.751 | K29: RTK | L29: 1.96 | M29: 633905.23 | N29: 3049240.4 | O29: 56.39 | P29: Altura antena 1,96 incluida en Zm vía data controller; por eso se corrigen en Excel Delta_ant y hm | Q29: 0.61 | R29: 2.57 | S29: 90 | U29: 0.54 | V29: 0.55 | W29: 0.78 | X29: 0.79 | Y29: 0.73 | AM29: =AVERAGE(U29:AC29) -> 0.678 | AN29: 3.67 | AQ29: =AN29-(AN29-Q29)*(SIN((S29+AX29)*PI()/180))/(COS(AX29*PI()/180)) -> 0.61 | AR29: =H29+($M$1-M29)-(AN29-Q29)*(COS(S29*PI()/180))*(SIN((T29+13+2.3)*PI()/180)) -> 633199.86 | AS29: =I29+($N$1-N29)-(AN29-Q29)*(COS(S29*PI()/180))*(COS((T29+13+2.3)*PI()/180)) -> 3046652.4 | AT29: =J29+($O$1-O29)-R29+AN29-(AN29-Q29)*(SIN(S29*PI()/180))-L29 -> 253.721
A30: EH26 | B30: 06-01-24 | C30: 14:47 | D30: NO | G30: rrc_20240106_gla | H30: 633235.35 | I30: 3046916.4 | J30: 261.746 | K30: RTK | L30: 0.001 | M30: 633905.23 | N30: 3049240.4 | O30: 56.39 | P30: Altura antena 0,001 incluida en Zm vía data controller; por eso se corrigen en Excel Delta_ant y hm. Sobre estaca | Q30: 1.23 | R30: 1.231 | S30: 90 | U30: 1.12 | V30: 1.1 | W30: 1.09 | X30: 1.15 | Y30: 1.12 | AM30: =AVERAGE(U30:AC30) -> 1.116 | AN30: 3.67 | AQ30: =AN30-(AN30-Q30)*(SIN((S30+AX30)*PI()/180))/(COS(AX30*PI()/180)) -> 1.23 | AR30: =H30+($M$1-M30)-(AN30-Q30)*(COS(S30*PI()/180))*(SIN((T30+13+2.3)*PI()/180)) -> 633235.35 | AS30: =I30+($N$1-N30)-(AN30-Q30)*(COS(S30*PI()/180))*(COS((T30+13+2.3)*PI()/180)) -> 3046916.4 | AT30: =J30+($O$1-O30)-R30+AN30-(AN30-Q30)*(SIN(S30*PI()/180))-L30 -> 261.634
A31: EH27 | B31: 03-01-24 | C31: 15:57 | D31: NO | G31: rrc_20240103_gla | H31: 632875.33 | I31: 3045648.2 | J31: 183.945 | K31: RTK | L31: 1.96 | M31: 633905.23 | N31: 3049240.4 | O31: 56.39 | P31: Altura antena 1,96 incluida en Zm vía data controller; por eso se corrigen en Excel Delta_ant y hm | Q31: 0.84 | R31: 2.8 | S31: 90 | U31: 0.88 | V31: 0.9 | W31: 0.9 | X31: 0.92 | Y31: 0.95 | AM31: =AVERAGE(U31:AC31) -> 0.91 | AN31: 3.67 | AQ31: =AN31-(AN31-Q31)*(SIN((S31+AX31)*PI()/180))/(COS(AX31*PI()/180)) -> 0.84 | AR31: =H31+($M$1-M31)-(AN31-Q31)*(COS(S31*PI()/180))*(SIN((T31+13+2.3)*PI()/180)) -> 632875.33 | AS31: =I31+($N$1-N31)-(AN31-Q31)*(COS(S31*PI()/180))*(COS((T31+13+2.3)*PI()/180)) -> 3045648.2 | AT31: =J31+($O$1-O31)-R31+AN31-(AN31-Q31)*(SIN(S31*PI()/180))-L31 -> 179.915
A32: EH28
A33: EH29
A34: EH30 | B34: 08-01-24 | C34: 14:57 | D34: NO | G34: rrc_20240108_gla | H34: 634270.1 | I34: 3046667.7 | J34: 319.387 | K34: RTK | L34: 1.96 | M34: 633905.23 | N34: 3049240.4 | O34: 56.39 | P34: Altura antena 1,96 incluida en Zm vía data controller; por eso se corrigen en Excel Delta_ant y hm | Q34: -0.21 | R34: 1.75 | S34: 90 | U34: 2.09 | V34: 2.02 | W34: 1.99 | X34: 2.14 | Y34: 2.2 | AM34: =AVERAGE(U34:AC34) -> 2.088 | AN34: 3.67 | AQ34: =AN34-(AN34-Q34)*(SIN((S34+AX34)*PI()/180))/(COS(AX34*PI()/180)) -> -0.21 | AR34: =H34+($M$1-M34)-(AN34-Q34)*(COS(S34*PI()/180))*(SIN((T34+13+2.3)*PI()/180)) -> 634270.1 | AS34: =I34+($N$1-N34)-(AN34-Q34)*(COS(S34*PI()/180))*(COS((T34+13+2.3)*PI()/180)) -> 3046667.7 | AT34: =J34+($O$1-O34)-R34+AN34-(AN34-Q34)*(SIN(S34*PI()/180))-L34 -> 315.357
A35: EH31
A36: EH32
A37: EH33
A38: EH34
A39: EH35
A40: EH36 | B40: 06-01-24 | C40: 15:37 | D40: NO | G40: rrc_20240106_gla | H40: 633315.32 | I40: 3047974.5 | J40: 143.582 | K40: RTK | L40: 0.115 | M40: 633905.23 | N40: 3049240.4 | O40: 56.39 | P40: Altura antena 0,115 incluida en Zm vía data controller; por eso se corrigen en Excel Delta_ant y hm | Q40: 1.02 | R40: 1.135 | S40: 90 | U40: 1.42 | V40: 1.47 | W40: 1.45 | X40: 1.5 | Y40: 1.47 | AM40: =AVERAGE(U40:AC40) -> 1.462 | AN40: 3.67 | AQ40: =AN40-(AN40-Q40)*(SIN((S40+AX40)*PI()/180))/(COS(AX40*PI()/180)) -> 1.02 | AR40: =H40+($M$1-M40)-(AN40-Q40)*(COS(S40*PI()/180))*(SIN((T40+13+2.3)*PI()/180)) -> 633315.32 | AS40: =I40+($N$1-N40)-(AN40-Q40)*(COS(S40*PI()/180))*(COS((T40+13+2.3)*PI()/180)) -> 3047974.5 | AT40: =J40+($O$1-O40)-R40+AN40-(AN40-Q40)*(SIN(S40*PI()/180))-L40 -> 143.242
A41: EH37
...

Sheet Estacas Hurd mto. 
A1: Campaña | B1: 2023-2024 | C1: Tanda | D1: a | E1: Operador | F1: Ricardo Rodríguez Cielos | G1: Instrumento | H1: Trimble R8S+TSC3(bluetooth) | L1: X0,Y0,Z0 | M1: 633905.22 | N1: 3049240.4 | O1: =56.475-0.11 -> 56.365 | P1: Mto. estacas HURD 1ª fase 2020/2021
A2: Id. estaca | B2: Fecha | C2: Hora (UT) | D2: ¿Mto.? | E2: PreMtoFecha | F2: PreMtoHora | G2: Fichero fuente | H2: Xm (E-UTM) | I2: Ym (N-UTM) | J2: Zm (WGS84) | K2: Código | L2: Dant | M2: Xr (E-UTM) | N2: Yr (N-UTM) | O2: Zr (WGS84) | P2: Comentarios sobre medida GPS | Q2: he (m) | R2: hm (m) | S2: e(deg) | T2: fm(deg) | Y2: H usados en media (m) | AH2: H no usados en media (m) | AM2: H (m) | AN2: l (m) | AO2: Comentarios medidas manuales | AP2: Recursos gráficos asociados | AQ2: h (m) | AR2: X (E-UTM) | AS2: Y (N-UTM) | AT2: Z (WGS84) | AU2: ¿40? | AV2: Coment. sobre medida corregida | AW2: Dh (m) | AX2: a(deg)
B3: dd-mm-aa | C3: hh:mm | D3: SÍ o vacío | E3: dd-mm-aa | F3: hh:mm | H3: xxxxxx,xx | I3: yyyyyyy,yy | J3: zzz,zz | M3: xxxxxx,xxx | N3: yyyyyyy,yyy | O3: zzz,zzz | Q3: hh,hh | R3: hh,hh | S3: g | T3: g | U3: H1 | V3: H2 | W3: H3 | X3: H4 | Y3: H5 | Z3: H6 | AA3: H7 | AB3: H8 | AC3: H9 | AD3: H1 | AE3: H2 | AF3: H3 | AG3: H4 | AH3: H5 | AI3: H6 | AJ3: H7 | AK3: H8 | AL3: H9 | AM3: HH,HH | AN3: ll,ll | AQ3: hh,hh | AR3: xxxxxx,xx | AS3: yyyyyyy,yy | AT3: zzz,zz | AW3: =AQ3-'Estacas Hurd'!AQ3 -> #VALUE!
A5: EH01 | D5: SÍ | S5: 90 | AM5: =AVERAGE(U5:AC5) -> #DIV/0! | AN5: 3.67 | AQ5: =AN5-(AN5-Q5)*(SIN((S5+AX5)*PI()/180))/(COS(AX5*PI()/180)) -> 0 | AR5: =H5+($M$1-M5)-(AN5-Q5)*(COS(S5*PI()/180))*(SIN((T5+13+2.3)*PI()/180)) -> 633905.22 | AS5: =I5+($N$1-N5)-(AN5-Q5)*(COS(S5*PI()/180))*(COS((T5+13+2.3)*PI()/180)) -> 3049240.4 | AT5: =J5+($O$1-O5)-R5+AN5-(AN5-Q5)*(SIN(S5*PI()/180))-L5 -> 56.365 | AW5: =AQ5-'Estacas Hurd'!AQ5 -> -0.11
A6: EH02 | D6: SÍ | S6: 90 | AM6: =AVERAGE(U6:AC6) -> #DIV/0! | AN6: 3.67 | AQ6: =AN6-(AN6-Q6)*(SIN((S6+AX6)*PI()/180))/(COS(AX6*PI()/180)) -> 0 | AR6: =H6+($M$1-M6)-(AN6-Q6)*(COS(S6*PI()/180))*(SIN((T6+13+2.3)*PI()/180)) -> 633905.22 | AS6: =I6+($N$1-N6)-(AN6-Q6)*(COS(S6*PI()/180))*(COS((T6+13+2.3)*PI()/180)) -> 3049240.4 | AT6: =J6+($O$1-O6)-R6+AN6-(AN6-Q6)*(SIN(S6*PI()/180))-L6 -> 56.365 | AW6: =AQ6-'Estacas Hurd'!AQ6 -> -0.31
A7: EH03 | D7: SÍ | S7: 90 | AM7: =AVERAGE(U7:AC7) -> #DIV/0! | AN7: 3.67 | AQ7: =AN7-(AN7-Q7)*(SIN((S7+AX7)*PI()/180))/(COS(AX7*PI()/180)) -> 0 | AR7: =H7+($M$1-M7)-(AN7-Q7)*(COS(S7*PI()/180))*(SIN((T7+13+2.3)*PI()/180)) -> 633905.22 | AS7: =I7+($N$1-N7)-(AN7-Q7)*(COS(S7*PI()/180))*(COS((T7+13+2.3)*PI()/180)) -> 3049240.4 | AT7: =J7+($O$1-O7)-R7+AN7-(AN7-Q7)*(SIN(S7*PI()/180))-L7 -> 56.365 | AW7: =AQ7-'Estacas Hurd'!AQ7 -> -0.03
A8: EH04 | D8: SÍ | S8: 90 | AM8: =AVERAGE(U8:AC8) -> #DIV/0! | AN8: 3.67 | AQ8: =AN8-(AN8-Q8)*(SIN((S8+AX8)*PI()/180))/(COS(AX8*PI()/180)) -> 0 | AR8: =H8+($M$1-M8)-(AN8-Q8)*(COS(S8*PI()/180))*(SIN((T8+13+2.3)*PI()/180)) -> 633905.22 | AS8: =I8+($N$1-N8)-(AN8-Q8)*(COS(S8*PI()/180))*(COS((T8+13+2.3)*PI()/180)) -> 3049240.4 | AT8: =J8+($O$1-O8)-R8+AN8-(AN8-Q8)*(SIN(S8*PI()/180))-L8 -> 56.365 | AW8: =AQ8-'Estacas Hurd'!AQ8 -> -0.3
A9: EH05 | D9: SÍ | S9: 90 | AM9: =AVERAGE(U9:AC9) -> #DIV/0! | AN9: 3.67 | AQ9: =AN9-(AN9-Q9)*(SIN((S9+AX9)*PI()/180))/(COS(AX9*PI()/180)) -> 0 | AR9: =H9+($M$1-M9)-(AN9-Q9)*(COS(S9*PI()/180))*(SIN((T9+13+2.3)*PI()/180)) -> 633905.22 | AS9: =I9+($N$1-N9)-(AN9-Q9)*(COS(S9*PI()/180))*(COS((T9+13+2.3)*PI()/180)) -> 3049240.4 | AT9: =J9+($O$1-O9)-R9+AN9-(AN9-Q9)*(SIN(S9*PI()/180))-L9 -> 56.365 | AW9: =AQ9-'Estacas Hurd'!AQ9 -> -1.03
A10: EH06 | D10: SÍ | S10: 90 | AM10: =AVERAGE(U10:AC10) -> #DIV/0! | AN10: 3.67 | AQ10: =AN10-(AN10-Q10)*(SIN((S10+AX10)*PI()/180))/(COS(AX10*PI()/180)) -> 0 | AR10: =H10+($M$1-M10)-(AN10-Q10)*(COS(S10*PI()/180))*(SIN((T10+13+2.3)*PI()/180)) -> 633905.22 | AS10: =I10+($N$1-N10)-(AN10-Q10)*(COS(S10*PI()/180))*(COS((T10+13+2.3)*PI()/180)) -> 3049240.4 | AT10: =J10+($O$1-O10)-R10+AN10-(AN10-Q10)*(SIN(S10*PI()/180))-L10 -> 56.365 | AW10: =AQ10-'Estacas Hurd'!AQ10 -> -0.14
A11: EH07
A12: EH08
A13: EH09
A14: EH10 | D14: SÍ | S14: 90 | AM14: =AVERAGE(U14:AC14) -> #DIV/0! | AN14: 3.67 | AQ14: =AN14-(AN14-Q14)*(SIN((S14+AX14)*PI()/180))/(COS(AX14*PI()/180)) -> 0 | AR14: =H14+($M$1-M14)-(AN14-Q14)*(COS(S14*PI()/180))*(SIN((T14+13+2.3)*PI()/180)) -> 633905.22 | AS14: =I14+($N$1-N14)-(AN14-Q14)*(COS(S14*PI()/180))*(COS((T14+13+2.3)*PI()/180)) -> 3049240.4 | AT14: =J14+($O$1-O14)-R14+AN14-(AN14-Q14)*(SIN(S14*PI()/180))-L14 -> 56.365 | AW14: =AQ14-'Estacas Hurd'!AQ14 -> -0.01
A15: EH11 | D15: SÍ | S15: 90 | AM15: =AVERAGE(U15:AC15) -> #DIV/0! | AN15: 3.67 | AQ15: =AN15-(AN15-Q15)*(SIN((S15+AX15)*PI()/180))/(COS(AX15*PI()/180)) -> 0 | AR15: =H15+($M$1-M15)-(AN15-Q15)*(COS(S15*PI()/180))*(SIN((T15+13+2.3)*PI()/180)) -> 633905.22 | AS15: =I15+($N$1-N15)-(AN15-Q15)*(COS(S15*PI()/180))*(COS((T15+13+2.3)*PI()/180)) -> 3049240.4 | AT15: =J15+($O$1-O15)-R15+AN15-(AN15-Q15)*(SIN(S15*PI()/180))-L15 -> 56.365 | AW15: =AQ15-'Estacas Hurd'!AQ15 -> -1.29
A16: EH12 | AW16: =AQ16-'Estacas Hurd'!AQ16 -> 0
A17: EH13
A18: EH14
A19: EH15
A20: EH16
A21: EH17
A22: EH18
A23: EH19
A24: EH20 | D24: SÍ | S24: 90 | AM24: =AVERAGE(U24:AC24) -> #DIV/0! | AN24: 3.67 | AQ24: =AN24-(AN24-Q24)*(SIN((S24+AX24)*PI()/180))/(COS(AX24*PI()/180)) -> 0 | AR24: =H24+($M$1-M24)-(AN24-Q24)*(COS(S24*PI()/180))*(SIN((T24+13+2.3)*PI()/180)) -> 633905.22 | AS24: =I24+($N$1-N24)-(AN24-Q24)*(COS(S24*PI()/180))*(COS((T24+13+2.3)*PI()/180)) -> 3049240.4 | AT24: =J24+($O$1-O24)-R24+AN24-(AN24-Q24)*(SIN(S24*PI()/180))-L24 -> 56.365 | AW24: =AQ24-'Estacas Hurd'!AQ24 -> -0.2
A25: EH21
A26: EH22 | D26: SÍ | S26: 90 | AM26: =AVERAGE(U26:AC26) -> #DIV/0! | AN26: 3.67 | AQ26: =AN26-(AN26-Q26)*(SIN((S26+AX26)*PI()/180))/(COS(AX26*PI()/180)) -> 0 | AR26: =H26+($M$1-M26)-(AN26-Q26)*(COS(S26*PI()/180))*(SIN((T26+13+2.3)*PI()/180)) -> 633905.22 | AS26: =I26+($N$1-N26)-(AN26-Q26)*(COS(S26*PI()/180))*(COS((T26+13+2.3)*PI()/180)) -> 3049240.4 | AT26: =J26+($O$1-O26)-R26+AN26-(AN26-Q26)*(SIN(S26*PI()/180))-L26 -> 56.365 | AW26: =AQ26-'Estacas Hurd'!AQ26 -> -0.46
A27: EH23 | D27: SÍ | S27: 90 | AM27: =AVERAGE(U27:AC27) -> #DIV/0! | AN27: 3.67 | AQ27: =AN27-(AN27-Q27)*(SIN((S27+AX27)*PI()/180))/(COS(AX27*PI()/180)) -> 0 | AR27: =H27+($M$1-M27)-(AN27-Q27)*(COS(S27*PI()/180))*(SIN((T27+13+2.3)*PI()/180)) -> 633905.22 | AS27: =I27+($N$1-N27)-(AN27-Q27)*(COS(S27*PI()/180))*(COS((T27+13+2.3)*PI()/180)) -> 3049240.4 | AT27: =J27+($O$1-O27)-R27+AN27-(AN27-Q27)*(SIN(S27*PI()/180))-L27 -> 56.365 | AW27: =AQ27-'Estacas Hurd'!AQ27 -> -0.27
A28: EH24
A29: EH25 | D29: SÍ | S29: 90 | AM29: =AVERAGE(U29:AC29) -> #DIV/0! | AN29: 3.67 | AQ29: =AN29-(AN29-Q29)*(SIN((S29+AX29)*PI()/180))/(COS(AX29*PI()/180)) -> 0 | AR29: =H29+($M$1-M29)-(AN29-Q29)*(COS(S29*PI()/180))*(SIN((T29+13+2.3)*PI()/180)) -> 633905.22 | AS29: =I29+($N$1-N29)-(AN29-Q29)*(COS(S29*PI()/180))*(COS((T29+13+2.3)*PI()/180)) -> 3049240.4 | AT29: =J29+($O$1-O29)-R29+AN29-(AN29-Q29)*(SIN(S29*PI()/180))-L29 -> 56.365 | AW29: =AQ29-'Estacas Hurd'!AQ29 -> -0.61
A30: EH26 | D30: SÍ | S30: 90 | AM30: =AVERAGE(U30:AC30) -> #DIV/0! | AN30: 3.67 | AQ30: =AN30-(AN30-Q30)*(SIN((S30+AX30)*PI()/180))/(COS(AX30*PI()/180)) -> 0 | AR30: =H30+($M$1-M30)-(AN30-Q30)*(COS(S30*PI()/180))*(SIN((T30+13+2.3)*PI()/180)) -> 633905.22 | AS30: =I30+($N$1-N30)-(AN30-Q30)*(COS(S30*PI()/180))*(COS((T30+13+2.3)*PI()/180)) -> 3049240.4 | AT30: =J30+($O$1-O30)-R30+AN30-(AN30-Q30)*(SIN(S30*PI()/180))-L30 -> 56.365 | AW30: =AQ30-'Estacas Hurd'!AQ30 -> -1.23
A31: EH27 | D31: SÍ | S31: 90 | AM31: =AVERAGE(U31:AC31) -> #DIV/0! | AN31: 3.67 | AQ31: =AN31-(AN31-Q31)*(SIN((S31+AX31)*PI()/180))/(COS(AX31*PI()/180)) -> 0 | AR31: =H31+($M$1-M31)-(AN31-Q31)*(COS(S31*PI()/180))*(SIN((T31+13+2.3)*PI()/180)) -> 633905.22 | AS31: =I31+($N$1-N31)-(AN31-Q31)*(COS(S31*PI()/180))*(COS((T31+13+2.3)*PI()/180)) -> 3049240.4 | AT31: =J31+($O$1-O31)-R31+AN31-(AN31-Q31)*(SIN(S31*PI()/180))-L31 -> 56.365 | AW31: =AQ31-'Estacas Hurd'!AQ31 -> -0.84
A32: EH28
A33: EH29
A34: EH30 | D34: SÍ | S34: 90 | AM34: =AVERAGE(U34:AC34) -> #DIV/0! | AN34: 3.67 | AQ34: =AN34-(AN34-Q34)*(SIN((S34+AX34)*PI()/180))/(COS(AX34*PI()/180)) -> 0 | AR34: =H34+($M$1-M34)-(AN34-Q34)*(COS(S34*PI()/180))*(SIN((T34+13+2.3)*PI()/180)) -> 633905.22 | AS34: =I34+($N$1-N34)-(AN34-Q34)*(COS(S34*PI()/180))*(COS((T34+13+2.3)*PI()/180)) -> 3049240.4 | AT34: =J34+($O$1-O34)-R34+AN34-(AN34-Q34)*(SIN(S34*PI()/180))-L34 -> 56.365 | AW34: =AQ34-'Estacas Hurd'!AQ34 -> 0.21
A35: EH31
A36: EH32
A37: EH33
A38: EH34
A39: EH35
A40: EH36 | D40: SÍ | S40: 90 | AM40: =AVERAGE(U40:AC40) -> #DIV/0! | AN40: 3.67 | AQ40: =AN40-(AN40-Q40)*(SIN((S40+AX40)*PI()/180))/(COS(AX40*PI()/180)) -> 0 | AR40: =H40+($M$1-M40)-(AN40-Q40)*(COS(S40*PI()/180))*(SIN((T40+13+2.3)*PI()/180)) -> 633905.22 | AS40: =I40+($N$1-N40)-(AN40-Q40)*(COS(S40*PI()/180))*(COS((T40+13+2.3)*PI()/180)) -> 3049240.4 | AT40: =J40+($O$1-O40)-R40+AN40-(AN40-Q40)*(SIN(S40*PI()/180))-L40 -> 56.365 | AW40: =AQ40-'Estacas Hurd'!AQ40 -> -1.02
A41: EH37
...

Sheet Estacas Johnsons
A1: Campaña | B1: 2023-2024 | C1: Tanda | D1: a | E1: Operador | F1: Ricardo Rodríguez Cielos | G1: Instrumento | H1: Trimble R8S+TSC3(bluetooth) | L1: X0,Y0,Z0 | M1: 633905.23 | N1: 3049240.4 | O1: =56.39-0.11 -> 56.28 | P1: Estacas JOHNSONS 1ª fase 2023/2024
A2: Id. estaca | B2: Fecha | C2: Hora (UT) | D2: ¿Mto.? | E2: PreMtoFecha | F2: PreMtoHora | G2: Fichero fuente | H2: Xm (E-UTM) | I2: Ym (N-UTM) | J2: Zm (WGS84) | K2: Código | L2: Dant | M2: Xr (E-UTM) | N2: Yr (N-UTM) | O2: Zr (WGS84) | P2: Comentarios sobre medida GPS | Q2: he (m) | R2: hm (m) | S2: e(deg) | T2: fm(deg) | Y2: H usados en media (m) | AH2: H no usados en media (m) | AM2: H (m) | AN2: l (m) | AO2: Comentarios medidas manuales | AP2: Recursos gráficos asociados | AQ2: h (m) | AR2: X (E-UTM) | AS2: Y (N-UTM) | AT2: Z (WGS84) | AU2: ¿40? | AV2: Coment. sobre medida corregida | AX2: a(deg)
B3: dd-mm-aa | C3: hh:mm | D3: Dejar NO | E3: Dejar vacío | F3: Dejar vacío | H3: xxxxxx,xx | I3: yyyyyyy,yy | J3: zzz,zz | M3: xxxxxx,xxx | N3: yyyyyyy,yyy | O3: zzz,zzz | Q3: hh,hh | R3: hh,hh | S3: g | T3: g | U3: H1 | V3: H2 | W3: H3 | X3: H4 | Y3: H5 | Z3: H6 | AA3: H7 | AB3: H8 | AC3: H9 | AD3: H1 | AE3: H2 | AF3: H3 | AG3: H4 | AH3: H5 | AI3: H6 | AJ3: H7 | AK3: H8 | AL3: H9 | AM3: HH,HH | AN3: ll,ll | AQ3: hh,hh | AR3: xxxxxx,xx | AS3: yyyyyyy,yy | AT3: zzz,zz
A5: EJ01
A6: EJ02
A7: EJ03 | B7: 08-01-24 | C7: 19:58 | D7: NO | G7: rrc_20240108_gla | H7: 635059.21 | I7: 3047841.6 | J7: 222.18 | K7: RTK | L7: 1.96 | M7: 633905.23 | N7: 3049240.4 | O7: 56.39 | P7: Altura antena 1,96 incluida en Zm vía data controller; por eso se corrigen en Excel Delta_ant y hm | Q7: -0.05 | R7: 1.91 | S7: 90 | U7: 1.87 | V7: 1.94 | W7: 1.79 | X7: 1.7 | Y7: 1.69 | AM7: =AVERAGE(U7:AC7) -> 1.798 | AN7: 3.67 | AQ7: =AN7-(AN7-Q7)*(SIN((S7+AX7)*PI()/180))/(COS(AX7*PI()/180)) -> -0.05 | AR7: =H7+($M$1-M7)-(AN7-Q7)*(COS(S7*PI()/180))*(SIN((T7+13+2.3)*PI()/180)) -> 635059.21 | AS7: =I7+($N$1-N7)-(AN7-Q7)*(COS(S7*PI()/180))*(COS((T7+13+2.3)*PI()/180)) -> 3047841.6 | AT7: =J7+($O$1-O7)-R7+AN7-(AN7-Q7)*(SIN(S7*PI()/180))-L7 -> 218.15
A8: EJ03r
A9: EJ04 | B9: 03-01-24 | C9: 18:36 | D9: NO | G9: rrc_20240103_gla | H9: 635107.04 | I9: 3048207.3 | J9: 185.095 | K9: RTK | L9: 1.96 | M9: 633905.23 | N9: 3049240.4 | O9: 56.39 | P9: Altura antena 1,96 incluida en Zm vía data controller; por eso se corrigen en Excel Delta_ant y hm | Q9: -0.25 | R9: 1.71 | S9: 90 | U9: 1.49 | V9: 1.53 | W9: 1.59 | X9: 1.54 | Y9: 1.55 | AM9: =AVERAGE(U9:AC9) -> 1.54 | AN9: 3.67 | AQ9: =AN9-(AN9-Q9)*(SIN((S9+AX9)*PI()/180))/(COS(AX9*PI()/180)) -> -0.25 | AR9: =H9+($M$1-M9)-(AN9-Q9)*(COS(S9*PI()/180))*(SIN((T9+13+2.3)*PI()/180)) -> 635107.04 | AS9: =I9+($N$1-N9)-(AN9-Q9)*(COS(S9*PI()/180))*(COS((T9+13+2.3)*PI()/180)) -> 3048207.3 | AT9: =J9+($O$1-O9)-R9+AN9-(AN9-Q9)*(SIN(S9*PI()/180))-L9 -> 181.065
A10: EJ04r
A11: EJ05 | B11: 05-01-24 | C11: 15:44 | D11: NO | G11: rrc_20240105_gla | H11: 635170.51 | I11: 3048653.1 | J11: 148.142 | K11: RTK | L11: 1.96 | M11: 633905.23 | N11: 3049240.4 | O11: 56.39 | P11: Altura antena 1,96 incluida en Zm vía data controller; por eso se corrigen en Excel Delta_ant y hm | Q11: -0.04 | R11: 1.92 | S11: 90 | U11: 0.79 | V11: 0.92 | W11: 0.93 | X11: 0.81 | Y11: 0.69 | AM11: =AVERAGE(U11:AC11) -> 0.828 | AN11: 3.67 | AQ11: =AN11-(AN11-Q11)*(SIN((S11+AX11)*PI()/180))/(COS(AX11*PI()/180)) -> -0.04 | AR11: =H11+($M$1-M11)-(AN11-Q11)*(COS(S11*PI()/180))*(SIN((T11+13+2.3)*PI()/180)) -> 635170.51 | AS11: =I11+($N$1-N11)-(AN11-Q11)*(COS(S11*PI()/180))*(COS((T11+13+2.3)*PI()/180)) -> 3048653.1 | AT11: =J11+($O$1-O11)-R11+AN11-(AN11-Q11)*(SIN(S11*PI()/180))-L11 -> 144.112
A12: EJ05r
A13: EJ06
A14: EJ06r
A15: EJ07
A16: EJ08
A17: EJ09 | B17: 04-01-24 | C17: 20:02 | D17: NO | G17: rrc_20240104_gla | H17: 636318.84 | I17: 3049668.5 | J17: 283.136 | K17: RTK | L17: 1.96 | M17: 633905.23 | N17: 3049240.4 | O17: 56.39 | P17: Altura antena 1,96 incluida en Zm vía data controller; por eso se corrigen en Excel Delta_ant y hm | Q17: -0.53 | R17: 1.43 | S17: 90 | U17: 2.4 | V17: 2.4 | W17: 2.4 | X17: 2.4 | Y17: 2.4 | AM17: =AVERAGE(U17:AC17) -> 2.4 | AN17: 3.67 | AQ17: =AN17-(AN17-Q17)*(SIN((S17+AX17)*PI()/180))/(COS(AX17*PI()/180)) -> -0.53 | AR17: =H17+($M$1-M17)-(AN17-Q17)*(COS(S17*PI()/180))*(SIN((T17+13+2.3)*PI()/180)) -> 636318.84 | AS17: =I17+($N$1-N17)-(AN17-Q17)*(COS(S17*PI()/180))*(COS((T17+13+2.3)*PI()/180)) -> 3049668.5 | AT17: =J17+($O$1-O17)-R17+AN17-(AN17-Q17)*(SIN(S17*PI()/180))-L17 -> 279.106
A18: EJ10 | B18: 04-01-24 | C18: 20:29 | D18: NO | G18: rrc_20240104_gla | H18: 635945.1 | I18: 3049411.7 | J18: 206.765 | K18: RTK | L18: 1.96 | M18: 633905.23 | N18: 3049240.4 | O18: 56.39 | P18: Altura antena 1,96 incluida en Zm vía data controller; por eso se corrigen en Excel Delta_ant y hm | Q18: -0.32 | R18: 1.64 | S18: 90 | U18: 1.46 | V18: 1.58 | W18: 1.64 | X18: 1.24 | Y18: 1.33 | AM18: =AVERAGE(U18:AC18) -> 1.45 | AN18: 3.67 | AQ18: =AN18-(AN18-Q18)*(SIN((S18+AX18)*PI()/180))/(COS(AX18*PI()/180)) -> -0.32 | AR18: =H18+($M$1-M18)-(AN18-Q18)*(COS(S18*PI()/180))*(SIN((T18+13+2.3)*PI()/180)) -> 635945.1 | AS18: =I18+($N$1-N18)-(AN18-Q18)*(COS(S18*PI()/180))*(COS((T18+13+2.3)*PI()/180)) -> 3049411.7 | AT18: =J18+($O$1-O18)-R18+AN18-(AN18-Q18)*(SIN(S18*PI()/180))-L18 -> 202.735
A19: EJ10r
A20: EJ11
A21: EJ11r
A22: EJ12
A23: EJ13
A24: EJ14
A25: EJ14r
A26: EJ15
A27: EJ16
A28: EJ16r
A29: EJ17
A30: EJ17r
... A36: EJ20r
A37: EJ21 | B37: 03-01-24 | C37: 19:27 | D37: NO | G37: rrc_20240103_gla | H37: 635908.13 | I37: 3047869.5 | J37: 214.458 | K37: RTK | L37: 1.96 | M37: 633905.23 | N37: 3049240.4 | O37: 56.39 | P37: Altura antena 1,96 incluida en Zm vía data controller; por eso se corrigen en Excel Delta_ant y hm | Q37: -0.28 | R37: 1.68 | S37: 90 | U37: 1.65 | V37: 1.62 | W37: 1.58 | X37: 1.58 | Y37: 1.6 | AM37: =AVERAGE(U37:AC37) -> 1.606 | AN37: 3.67 | AQ37: =AN37-(AN37-Q37)*(SIN((S37+AX37)*PI()/180))/(COS(AX37*PI()/180)) -> -0.28 | AR37: =H37+($M$1-M37)-(AN37-Q37)*(COS(S37*PI()/180))*(SIN((T37+13+2.3)*PI()/180)) -> 635908.13 | AS37: =I37+($N$1-N37)-(AN37-Q37)*(COS(S37*PI()/180))*(COS((T37+13+2.3)*PI()/180)) -> 3047869.5 | AT37: =J37+($O$1-O37)-R37+AN37-(AN37-Q37)*(SIN(S37*PI()/180))-L37 -> 210.428
A38: EJ22 | B38: 03-01-24 | C38: 18:54 | D38: NO | G38: rrc_20240103_gla | H38: 635711.83 | I38: 3048163.6 | J38: 195.029 | K38: RTK | L38: 0.001 | M38: 633905.23 | N38: 3049240.4 | O38: 56.39 | P38: Altura antena 0,001 incluida en Zm vía data controller; por eso se corrigen en Excel Delta_ant y hm. Sobre estaca | Q38: 0.96 | R38: 0.961 | S38: 90 | U38: 1.32 | V38: 1.25 | W38: 1.26 | X38: 1.3 | Y38: 1.28 | AM38: =AVERAGE(U38:AC38) -> 1.282 | AN38: 3.67 | AQ38: =AN38-(AN38-Q38)*(SIN((S38+AX38)*PI()/180))/(COS(AX38*PI()/180)) -> 0.96 | AR38: =H38+($M$1-M38)-(AN38-Q38)*(COS(S38*PI()/180))*(SIN((T38+13+2.3)*PI()/180)) -> 635711.83 | AS38: =I38+($N$1-N38)-(AN38-Q38)*(COS(S38*PI()/180))*(COS((T38+13+2.3)*PI()/180)) -> 3048163.6 | AT38: =J38+($O$1-O38)-R38+AN38-(AN38-Q38)*(SIN(S38*PI()/180))-L38 -> 194.917
A39: EJ23 | B39: 03-01-24 | C39: 19:01 | D39: NO | G39: rrc_20240103_gla | H39: 635601.46 | I39: 3048422.4 | J39: 174.999 | K39: RTK | L39: 0.001 | M39: 633905.23 | N39: 3049240.4 | O39: 56.39 | P39: Altura antena 0,001 incluida en Zm vía data controller; por eso se corrigen en Excel Delta_ant y hm. Sobre estaca | Q39: 0.92 | R39: 0.921 | S39: 90 | U39: 1.5 | V39: 1.45 | W39: 1.38 | X39: 1.4 | Y39: 1.44 | AM39: =AVERAGE(U39:AC39) -> 1.434 | AN39: 3.67 | AQ39: =AN39-(AN39-Q39)*(SIN((S39+AX39)*PI()/180))/(COS(AX39*PI()/180)) -> 0.92 | AR39: =H39+($M$1-M39)-(AN39-Q39)*(COS(S39*PI()/180))*(SIN((T39+13+2.3)*PI()/180)) -> 635601.46 | AS39: =I39+($N$1-N39)-(AN39-Q39)*(COS(S39*PI()/180))*(COS((T39+13+2.3)*PI()/180)) -> 3048422.4 | AT39: =J39+($O$1-O39)-R39+AN39-(AN39-Q39)*(SIN(S39*PI()/180))-L39 -> 174.887
A40: EJ24 | B40: 04-01-24 | C40: 17:15 | D40: NO | G40: rrc_20240104_gla | H40: 635518.94 | I40: 3047623.4 | J40: 230.059 | K40: RTK | L40: 1.96 | M40: 633905.23 | N40: 3049240.4 | O40: 56.39 | P40: Altura antena 0,78 incluida en Zm vía data controller; por eso se corrigen en Excel Delta_ant y hm | Q40: 0.48 | R40: 2.44 | S40: 90 | U40: 1.52 | V40: 1.65 | W40: 1.52 | X40: 1.51 | Y40: 1.55 | AM40: =AVERAGE(U40:AC40) -> 1.55 | AN40: 3.67 | AQ40: =AN40-(AN40-Q40)*(SIN((S40+AX40)*PI()/180))/(COS(AX40*PI()/180)) -> 0.48 | AR40: =H40+($M$1-M40)-(AN40-Q40)*(COS(S40*PI()/180))*(SIN((T40+13+2.3)*PI()/180)) -> 635518.94 | AS40: =I40+($N$1-N40)-(AN40-Q40)*(COS(S40*PI()/180))*(COS((T40+13+2.3)*PI()/180)) -> 3047623.4 | AT40: =J40+($O$1-O40)-R40+AN40-(AN40-Q40)*(SIN(S40*PI()/180))-L40 -> 226.029
A41: EJ25
A42: EJ26 | B42: 04-01-24 | C42: 20:13 | D42: NO | G42: rrc_20240104_gla | H42: 636212.07 | I42: 3049089.3 | J42: 212.643 | K42: RTK | L42: 1.96 | M42: 633905.23 | N42: 3049240.4 | O42: 56.39 | P42: Altura antena 1,96 incluida en Zm vía data controller; por eso se corrigen en Excel Delta_ant y hm | Q42: -0.12 | R42: 1.84 | S42: 90 | U42: 2.1 | V42: 2.15 | W42: 2.05 | X42: 1.98 | Y42: 2.02 | AM42: =AVERAGE(U42:AC42) -> 2.06 | AN42: 3.67 | AQ42: =AN42-(AN42-Q42)*(SIN((S42+AX42)*PI()/180))/(COS(AX42*PI()/180)) -> -0.12 | AR42: =H42+($M$1-M42)-(AN42-Q42)*(COS(S42*PI()/180))*(SIN((T42+13+2.3)*PI()/180)) -> 636212.07 | AS42: =I42+($N$1-N42)-(AN42-Q42)*(COS(S42*PI()/180))*(COS((T42+13+2.3)*PI()/180)) -> 3049089.3 | AT42: =J42+($O$1-O42)-R42+AN42-(AN42-Q42)*(SIN(S42*PI()/180))-L42 -> 208.613
A43: EJ27 | B43: 05-01-24 | C43: 15:44 | D43: NO | G43: rrc_20240105_gla | H43: 635838.09 | I43: 3049042.6 | J43: 173.457 | K43: RTK | L43: 0.47 | M43: 633905.23 | N43: 3049240.4 | O43: 56.39 | P43: Altura antena 0,47 incluida en Zm vía data controller; por eso se corrigen en Excel Delta_ant y hm | Q43: 0.95 | R43: 1.42 | S43: 90 | U43: 1.21 | V43: 1.25 | W43: 1.28 | X43: 0.94 | Y43: 1.22 | AM43: =AVERAGE(U43:AC43) -> 1.18 | AN43: 3.67 | AQ43: =AN43-(AN43-Q43)*(SIN((S43+AX43)*PI()/180))/(COS(AX43*PI()/180)) -> 0.95 | AR43: =H43+($M$1-M43)-(AN43-Q43)*(COS(S43*PI()/180))*(SIN((T43+13+2.3)*PI()/180)) -> 635838.09 | AS43: =I43+($N$1-N43)-(AN43-Q43)*(COS(S43*PI()/180))*(COS((T43+13+2.3)*PI()/180)) -> 3049042.6 | AT43: =J43+($O$1-O43)-R43+AN43-(AN43-Q43)*(SIN(S43*PI()/180))-L43 -> 172.407
A44: EJ28
A45: EJ29
A46: EJ30 | B46: 04-01-24 | C46: 19:42 | D46: NO | G46: rrc_20240104_gla | H46: 636674.35 | I46: 3049165.8 | J46: 248.898 | K46: RTK | L46: 1.96 | M46: 633905.23 | N46: 3049240.4 | O46: 56.39 | P46: Altura antena 1,96 incluida en Zm vía data controller; por eso se corrigen en Excel Delta_ant y hm | Q46: -0.14 | R46: 1.82 | S46: 90 | U46: 1.93 | V46: 1.95 | W46: 1.96 | X46: 1.96 | Y46: 1.92 | AM46: =AVERAGE(U46:AC46) -> 1.944 | AN46: 3.67 | AQ46: =AN46-(AN46-Q46)*(SIN((S46+AX46)*PI()/180))/(COS(AX46*PI()/180)) -> -0.14 | AR46: =H46+($M$1-M46)-(AN46-Q46)*(COS(S46*PI()/180))*(SIN((T46+13+2.3)*PI()/180)) -> 636674.35 | AS46: =I46+($N$1-N46)-(AN46-Q46)*(COS(S46*PI()/180))*(COS((T46+13+2.3)*PI()/180)) -> 3049165.8 | AT46: =J46+($O$1-O46)-R46+AN46-(AN46-Q46)*(SIN(S46*PI()/180))-L46 -> 244.868
...

Sheet Estacas Johnsons mto.
A1: Campaña | B1: 2023-2024 | C1: Tanda | D1: a | E1: Operador | F1: Ricardo Rodríguez Cielos | G1: Instrumento | H1: Trimble R8S+TSC3(bluetooth) | L1: X0,Y0,Z0 | M1: 633905.22 | N1: 3049240.4 | O1: =56.475-0.11 -> 56.365 | P1: Mto. estacas JOHNSONS 1ª fase 2023/2024
A2: Id. estaca | B2: Fecha | C2: Hora (UT) | D2: ¿Mto.? | E2: PreMtoFecha | F2: PreMtoHora | G2: Fichero fuente | H2: Xm (E-UTM) | I2: Ym (N-UTM) | J2: Zm (WGS84) | K2: Código | L2: Dant | M2: Xr (E-UTM) | N2: Yr (N-UTM) | O2: Zr (WGS84) | P2: Comentarios sobre medida GPS | Q2: he (m) | R2: hm (m) | S2: e(deg) | T2: fm(deg) | Y2: H usados en media (m) | AH2: H no usados en media (m) | AM2: H (m) | AN2: l (m) | AO2: Comentarios medidas manuales | AP2: Recursos gráficos asociados | AQ2: h (m) | AR2: X (E-UTM) | AS2: Y (N-UTM) | AT2: Z (WGS84) | AU2: ¿40? | AV2: Coment. sobre medida corregida | AW2: Dh (m) | AX2: a(deg)
B3: dd-mm-aa | C3: hh:mm | D3: SÍ o vacío | E3: dd-mm-aa | F3: hh:mm | H3: Jaime Otero y Unai Letamendia | I3: yyyyyyy,yy | J3: zzz,zz | M3: xxxxxx,xxx | N3: yyyyyyy,yyy | O3: zzz,zzz | Q3: hh,hh | R3: hh,hh | S3: g | AQ3: hh,hh | AR3: xxxxxx,xx | AS3: yyyyyyy,yy | AT3: zzz,zz
A5: EJ01
A6: EJ02
A7: EJ03 | D7: SÍ | S7: 90 | AM7: =AVERAGE(U7:AC7) -> #DIV/0! | AN7: 3.67 | AQ7: =AN7-(AN7-Q7)*(SIN((S7+AX7)*PI()/180))/(COS(AX7*PI()/180)) -> 0 | AR7: =H7+($M$1-M7)-(AN7-Q7)*(COS(S7*PI()/180))*(SIN((T7+13+2.3)*PI()/180)) -> 633905.22 | AS7: =I7+($N$1-N7)-(AN7-Q7)*(COS(S7*PI()/180))*(COS((T7+13+2.3)*PI()/180)) -> 3049240.4 | AT7: =J7+($O$1-O7)-R7+AN7-(AN7-Q7)*(SIN(S7*PI()/180))-L7 -> 56.365 | AW7: =AQ7-'Estacas Johnsons'!AQ7 -> 0.05
A8: EJ03r
A9: EJ04 | D9: SÍ | S9: 90 | AM9: =AVERAGE(U9:AC9) -> #DIV/0! | AN9: 3.67 | AQ9: =AN9-(AN9-Q9)*(SIN((S9+AX9)*PI()/180))/(COS(AX9*PI()/180)) -> 0 | AR9: =H9+($M$1-M9)-(AN9-Q9)*(COS(S9*PI()/180))*(SIN((T9+13+2.3)*PI()/180)) -> 633905.22 | AS9: =I9+($N$1-N9)-(AN9-Q9)*(COS(S9*PI()/180))*(COS((T9+13+2.3)*PI()/180)) -> 3049240.4 | AT9: =J9+($O$1-O9)-R9+AN9-(AN9-Q9)*(SIN(S9*PI()/180))-L9 -> 56.365 | AW9: =AQ9-'Estacas Johnsons'!AQ9 -> 0.25
A10: EJ04r
A11: EJ05 | D11: SÍ | S11: 90 | AM11: =AVERAGE(U11:AC11) -> #DIV/0! | AN11: 3.67 | AQ11: =AN11-(AN11-Q11)*(SIN((S11+AX11)*PI()/180))/(COS(AX11*PI()/180)) -> 0 | AR11: =H11+($M$1-M11)-(AN11-Q11)*(COS(S11*PI()/180))*(SIN((T11+13+2.3)*PI()/180)) -> 633905.22 | AS11: =I11+($N$1-N11)-(AN11-Q11)*(COS(S11*PI()/180))*(COS((T11+13+2.3)*PI()/180)) -> 3049240.4 | AT11: =J11+($O$1-O11)-R11+AN11-(AN11-Q11)*(SIN(S11*PI()/180))-L11 -> 56.365 | AW11: =AQ11-'Estacas Johnsons'!AQ11 -> 0.04
A12: EJ05r
A13: EJ06
A14: EJ06r
A15: EJ07
A16: EJ08
A17: EJ09 | D17: SÍ | S17: 90 | AM17: =AVERAGE(U17:AC17) -> #DIV/0! | AN17: 3.67
A18: EJ10 | D18: SÍ | S18: 90 | AM18: =AVERAGE(U18:AC18) -> #DIV/0! | AN18: 3.67 | AQ18: =AN18-(AN18-Q18)*(SIN((S18+AX18)*PI()/180))/(COS(AX18*PI()/180)) -> 0 | AR18: =H18+($M$1-M18)-(AN18-Q18)*(COS(S18*PI()/180))*(SIN((T18+13+2.3)*PI()/180)) -> 633905.22 | AS18: =I18+($N$1-N18)-(AN18-Q18)*(COS(S18*PI()/180))*(COS((T18+13+2.3)*PI()/180)) -> 3049240.4 | AT18: =J18+($O$1-O18)-R18+AN18-(AN18-Q18)*(SIN(S18*PI()/180))-L18 -> 56.365 | AW18: =AQ18-'Estacas Johnsons'!AQ18 -> 0.32
A19: EJ10r
A20: EJ11
A21: EJ11r
A22: EJ12
A23: EJ13
A24: EJ14
A25: EJ14r
A26: EJ15
A27: EJ16
A28: EJ16r
A29: EJ17
A30: EJ17r
... A36: EJ20r
A37: EJ21 | D37: SÍ | S37: 90 | AM37: =AVERAGE(U37:AC37) -> #DIV/0! | AN37: 3.67 | AQ37: =AN37-(AN37-Q37)*(SIN((S37+AX37)*PI()/180))/(COS(AX37*PI()/180)) -> 0 | AR37: =H37+($M$1-M37)-(AN37-Q37)*(COS(S37*PI()/180))*(SIN((T37+13+2.3)*PI()/180)) -> 633905.22 | AS37: =I37+($N$1-N37)-(AN37-Q37)*(COS(S37*PI()/180))*(COS((T37+13+2.3)*PI()/180)) -> 3049240.4 | AT37: =J37+($O$1-O37)-R37+AN37-(AN37-Q37)*(SIN(S37*PI()/180))-L37 -> 56.365 | AW37: =AQ37-'Estacas Johnsons'!AQ37 -> 0.28
A38: EJ22 | D38: SÍ | S38: 90 | AM38: =AVERAGE(U38:AC38) -> #DIV/0! | AN38: 3.67 | AQ38: =AN38-(AN38-Q38)*(SIN((S38+AX38)*PI()/180))/(COS(AX38*PI()/180)) -> 0 | AR38: =H38+($M$1-M38)-(AN38-Q38)*(COS(S38*PI()/180))*(SIN((T38+13+2.3)*PI()/180)) -> 633905.22 | AS38: =I38+($N$1-N38)-(AN38-Q38)*(COS(S38*PI()/180))*(COS((T38+13+2.3)*PI()/180)) -> 3049240.4 | AT38: =J38+($O$1-O38)-R38+AN38-(AN38-Q38)*(SIN(S38*PI()/180))-L38 -> 56.365 | AW38: =AQ38-'Estacas Johnsons'!AQ38 -> -0.96
A39: EJ23 | D39: SÍ | S39: 90 | AM39: =AVERAGE(U39:AC39) -> #DIV/0! | AN39: 3.67 | AQ39: =AN39-(AN39-Q39)*(SIN((S39+AX39)*PI()/180))/(COS(AX39*PI()/180)) -> 0 | AR39: =H39+($M$1-M39)-(AN39-Q39)*(COS(S39*PI()/180))*(SIN((T39+13+2.3)*PI()/180)) -> 633905.22 | AS39: =I39+($N$1-N39)-(AN39-Q39)*(COS(S39*PI()/180))*(COS((T39+13+2.3)*PI()/180)) -> 3049240.4 | AT39: =J39+($O$1-O39)-R39+AN39-(AN39-Q39)*(SIN(S39*PI()/180))-L39 -> 56.365 | AW39: =AQ39-'Estacas Johnsons'!AQ39 -> -0.92
A40: EJ24 | D40: SÍ | S40: 90 | AM40: =AVERAGE(U40:AC40) -> #DIV/0! | AN40: 3.67 | AQ40: =AN40-(AN40-Q40)*(SIN((S40+AX40)*PI()/180))/(COS(AX40*PI()/180)) -> 0 | AR40: =H40+($M$1-M40)-(AN40-Q40)*(COS(S40*PI()/180))*(SIN((T40+13+2.3)*PI()/180)) -> 633905.22 | AS40: =I40+($N$1-N40)-(AN40-Q40)*(COS(S40*PI()/180))*(COS((T40+13+2.3)*PI()/180)) -> 3049240.4 | AT40: =J40+($O$1-O40)-R40+AN40-(AN40-Q40)*(SIN(S40*PI()/180))-L40 -> 56.365 | AW40: =AQ40-'Estacas Johnsons'!AQ40 -> -0.48
A41: EJ25
A42: EJ26 | D42: SÍ | S42: 90 | AM42: =AVERAGE(U42:AC42) -> #DIV/0! | AN42: 3.67 | AQ42: =AN42-(AN42-Q42)*(SIN((S42+AX42)*PI()/180))/(COS(AX42*PI()/180)) -> 0 | AR42: =H42+($M$1-M42)-(AN42-Q42)*(COS(S42*PI()/180))*(SIN((T42+13+2.3)*PI()/180)) -> 633905.22 | AS42: =I42+($N$1-N42)-(AN42-Q42)*(COS(S42*PI()/180))*(COS((T42+13+2.3)*PI()/180)) -> 3049240.4 | AT42: =J42+($O$1-O42)-R42+AN42-(AN42-Q42)*(SIN(S42*PI()/180))-L42 -> 56.365 | AW42: =AQ42-'Estacas Johnsons'!AQ42 -> 0.12
A43: EJ27 | D43: SÍ | S43: 90 | AM43: =AVERAGE(U43:AC43) -> #DIV/0! | AN43: 3.67 | AQ43: =AN43-(AN43-Q43)*(SIN((S43+AX43)*PI()/180))/(COS(AX43*PI()/180)) -> 0 | AR43: =H43+($M$1-M43)-(AN43-Q43)*(COS(S43*PI()/180))*(SIN((T43+13+2.3)*PI()/180)) -> 633905.22 | AS43: =I43+($N$1-N43)-(AN43-Q43)*(COS(S43*PI()/180))*(COS((T43+13+2.3)*PI()/180)) -> 3049240.4 | AT43: =J43+($O$1-O43)-R43+AN43-(AN43-Q43)*(SIN(S43*PI()/180))-L43 -> 56.365 | AW43: =AQ43-'Estacas Johnsons'!AQ43 -> -0.95
A44: EJ28
A45: EJ29
A46: EJ30 | D46: SÍ | S46: 90 | AM46: =AVERAGE(U46:AC46) -> #DIV/0! | AN46: 3.67 | AQ46: =AN46-(AN46-Q46)*(SIN((S46+AX46)*PI()/180))/(COS(AX46*PI()/180)) -> 0 | AR46: =H46+($M$1-M46)-(AN46-Q46)*(COS(S46*PI()/180))*(SIN((T46+13+2.3)*PI()/180)) -> 633905.22 | AS46: =I46+($N$1-N46)-(AN46-Q46)*(COS(S46*PI()/180))*(COS((T46+13+2.3)*PI()/180)) -> 3049240.4 | AT46: =J46+($O$1-O46)-R46+AN46-(AN46-Q46)*(SIN(S46*PI()/180))-L46 -> 56.365 | AW46: =AQ46-'Estacas Johnsons'!AQ46 -> 0.14
...

Sheet RED PUNTOS CONTROL
A1: Campaña | B1: 2023-2024 | C1: Tanda | D1: a | E1: Operador | F1: Ricardo Rodríguez Cielos | G1: Instrumento | H1: Trimble R8S+TSC3(bluetooth) | K1: Medidas del punto de control junto al refugio de montaña
A2: Id.punto | B2: Fecha | C2: Hora (UT) | D2: Fichero fuente | E2: Xm (E-UTM) | F2: Ym (N-UTM) | G2: Zm (WGS84) | H2: Código | I2: Dant | J2: Xr (E-UTM) | K2: Yr (N-UTM) | L2: Zr (WGS84) | M2: Comentarios sobre medida GPS | N2: X (E-UTM) | O2: Y (N-UTM) | P2: Z (WGS84)
B3: dd-mm-aa | C3: hh:mm | E3: xxxxxx,xx | F3: yyyyyyy,yy | G3: zzz,zz | J3: xxxxxx,xxx | K3: yyyyyyy,yyy | L3: zzz,zzz | N3: xxxxxx,xx | O3: yyyyyyy,yy | P3: zzz,zz
N5: =E5 -> 0 | O5: =F5 -> 0 | P5: =G5-I5 -> 0
N6: =E6 -> 0 | O6: =F6 -> 0 | P6: =G6-I6 -> 0
N7: =E7 -> 0 | O7: =F7 -> 0 | P7: =G7-I7 -> 0
N8: =E8 -> 0 | O8: =F8 -> 0 | P8: =G8-I8 -> 0
N9: =E9 -> 0 | O9: =F9 -> 0 | P9: =G9-I9 -> 0
N10: =E10 -> 0 | O10: =F10 -> 0 | P10: =G10-I10 -> 0
N11: =E11 -> 0 | O11: =F11 -> 0 | P11: =G11-I11 -> 0
N12: =E12 -> 0 | O12: =F12 -> 0 | P12: =G12-I12 -> 0
N13: =E13 -> 0 | O13: =F13 -> 0 | P13: =G13-I13 -> 0
N14: =E14 -> 0 | O14: =F14 -> 0 | P14: =G14-I14 -> 0
N15: =E15 -> 0 | O15: =F15 -> 0 | P15: =G15-I15 -> 0
N16: =E16 -> 0 | O16: =F16 -> 0 | P16: =G16-I16 -> 0
... N23: =E23 -> 0 | O23: =F23 -> 0 | P23: =G23-I23 -> 0

Sheet CorrInclinSepult
A1: Id. estaca | B1: Xm* (E-UTM) | C1: Ym* (N-UTM) | D1: Zm* (WGS84) | E1: e(deg) | F1: fm(deg) | G1: he* (m) | H1: hm* (m) | I1: a(deg) | J1: he (m) | K1: hm = hm*(m) | L1: Xm (E-UTM) | M1: Ym (N-UTM) | N1: Zm (WGS84)
J2: =G2*COS(I2*PI()/180)/SIN((E2+I2)*PI()/180) -> #DIV/0! | K2: =H2 -> 0 | L2: =B2-(J2*COS(E2*PI()/180))*SIN((F2-13)*PI()/180) -> #DIV/0! | M2: =C2-(J2*COS(E2*PI()/180))*COS((F2-13)*PI()/180) -> #DIV/0! | N2: =D2+G2*COS(E2*PI()/180)*SIN(I2*PI()/180)/SIN((E2+I2)*PI()/180) -> #DIV/0!
J3: =G3*COS(I3*PI()/180)/SIN((E3+I3)*PI()/180) -> #DIV/0! | K3: =H3 -> 0 | L3: =B3-(J3*COS(E3*PI()/180))*SIN((F3-13)*PI()/180) -> #DIV/0! | M3: =C3-(J3*COS(E3*PI()/180))*COS((F3-13)*PI()/180) -> #DIV/0! | N3: =D3+G3*COS(E3*PI()/180)*SIN(I3*PI()/180)/SIN((E3+I3)*PI()/180) -> #DIV/0!
J4: =G4*COS(I4*PI()/180)/SIN((E4+I4)*PI()/180) -> #DIV/0! | K4: =H4 -> 0 | L4: =B4-(J4*COS(E4*PI()/180))*SIN((F4-13)*PI()/180) -> #DIV/0! | M4: =C4-(J4*COS(E4*PI()/180))*COS((F4-13)*PI()/180) -> #DIV/0! | N4: =D4+G4*COS(E4*PI()/180)*SIN(I4*PI()/180)/SIN((E4+I4)*PI()/180) -> #DIV/0!
J5: =G5*COS(I5*PI()/180)/SIN((E5+I5)*PI()/180) -> #DIV/0! | K5: =H5 -> 0 | L5: =B5-(J5*COS(E5*PI()/180))*SIN((F5-13)*PI()/180) -> #DIV/0! | M5: =C5-(J5*COS(E5*PI()/180))*COS((F5-13)*PI()/180) -> #DIV/0! | N5: =D5+G5*COS(E5*PI()/180)*SIN(I5*PI()/180)/SIN((E5+I5)*PI()/180) -> #DIV/0!
J6: =G6*COS(I6*PI()/180)/SIN((E6+I6)*PI()/180) -> #DIV/0! | K6: =H6 -> 0 | L6: =B6-(J6*COS(E6*PI()/180))*SIN((F6-13)*PI()/180) -> #DIV/0! | M6: =C6-(J6*COS(E6*PI()/180))*COS((F6-13)*PI()/180) -> #DIV/0! | N6: =D6+G6*COS(E6*PI()/180)*SIN(I6*PI()/180)/SIN((E6+I6)*PI()/180) -> #DIV/0!
J7: =G7*COS(I7*PI()/180)/SIN((E7+I7)*PI()/180) -> #DIV/0! | K7: =H7 -> 0 | L7: =B7-(J7*COS(E7*PI()/180))*SIN((F7-13)*PI()/180) -> #DIV/0! | M7: =C7-(J7*COS(E7*PI()/180))*COS((F7-13)*PI()/180) -> #DIV/0! | N7: =D7+G7*COS(E7*PI()/180)*SIN(I7*PI()/180)/SIN((E7+I7)*PI()/180) -> #DIV/0!
J8: =G8*COS(I8*PI()/180)/SIN((E8+I8)*PI()/180) -> #DIV/0! | K8: =H8 -> 0 | L8: =B8-(J8*COS(E8*PI()/180))*SIN((F8-13)*PI()/180) -> #DIV/0! | M8: =C8-(J8*COS(E8*PI()/180))*COS((F8-13)*PI()/180) -> #DIV/0! | N8: =D8+G8*COS(E8*PI()/180)*SIN(I8*PI()/180)/SIN((E8+I8)*PI()/180) -> #DIV/0!
J9: =G9*COS(I9*PI()/180)/SIN((E9+I9)*PI()/180) -> #DIV/0! | K9: =H9 -> 0 | L9: =B9-(J9*COS(E9*PI()/180))*SIN((F9-13)*PI()/180) -> #DIV/0! | M9: =C9-(J9*COS(E9*PI()/180))*COS((F9-13)*PI()/180) -> #DIV/0! | N9: =D9+G9*COS(E9*PI()/180)*SIN(I9*PI()/180)/SIN((E9+I9)*PI()/180) -> #DIV/0!
J10: =G10*COS(I10*PI()/180)/SIN((E10+I10)*PI()/180) -> #DIV/0! | K10: =H10 -> 0 | L10: =B10-(J10*COS(E10*PI()/180))*SIN((F10-13)*PI()/180) -> #DIV/0! | M10: =C10-(J10*COS(E10*PI()/180))*COS((F10-13)*PI()/180) -> #DIV/0! | N10: =D10+G10*COS(E10*PI()/180)*SIN(I10*PI()/180)/SIN((E10+I10)*PI()/180) -> #DIV/0!
J11: =G11*COS(I11*PI()/180)/SIN((E11+I11)*PI()/180) -> #DIV/0! | K11: =H11 -> 0 | L11: =B11-(J11*COS(E11*PI()/180))*SIN((F11-13)*PI()/180) -> #DIV/0! | M11: =C11-(J11*COS(E11*PI()/180))*COS((F11-13)*PI()/180) -> #DIV/0! | N11: =D11+G11*COS(E11*PI()/180)*SIN(I11*PI()/180)/SIN((E11+I11)*PI()/180) -> #DIV/0!
J12: =G12*COS(I12*PI()/180)/SIN((E12+I12)*PI()/180) -> #DIV/0! | K12: =H12 -> 0 | L12: =B12-(J12*COS(E12*PI()/180))*SIN((F12-13)*PI()/180) -> #DIV/0! | M12: =C12-(J12*COS(E12*PI()/180))*COS((F12-13)*PI()/180) -> #DIV/0! | N12: =D12+G12*COS(E12*PI()/180)*SIN(I12*PI()/180)/SIN((E12+I12)*PI()/180) -> #DIV/0!
J13: =G13*COS(I13*PI()/180)/SIN((E13+I13)*PI()/180) -> #DIV/0! | K13: =H13 -> 0 | L13: =B13-(J13*COS(E13*PI()/180))*SIN((F13-13)*PI()/180) -> #DIV/0! | M13: =C13-(J13*COS(E13*PI()/180))*COS((F13-13)*PI()/180) -> #DIV/0! | N13: =D13+G13*COS(E13*PI()/180)*SIN(I13*PI()/180)/SIN((E13+I13)*PI()/180) -> #DIV/0!
... J25: =G25*COS(I25*PI()/180)/SIN((E25+I25)*PI()/180) -> #DIV/0! | K25: =H25 -> 0 | L25: =B25-(J25*COS(E25*PI()/180))*SIN((F25-13)*PI()/180) -> #DIV/0! | M25: =C25-(J25*COS(E25*PI()/180))*COS((F25-13)*PI()/180) -> #DIV/0! | N25: =D25+G25*COS(E25*PI()/180)*SIN(I25*PI()/180)/SIN((E25+I25)*PI()/180) -> #DIV/0!

Sheet Estacas Campo
A1: ESTACAS CAMPO
A2: Campaña: | E2: Tanda: | G2: Fecha: | I2: Operador:
A3: Estaca | B3: Hora local | C3: he(cm) | D3: hm(cm) | E3: e (deg) | F3: fm (deg) | G3: a (deg) | H3: H (cm) (varios valores) | I3: l (cm) | J3: Comentarios
